<?xml version="1.0" ?>
<!-- =================================================================================== -->
<!-- |    This document was autogenerated by xacro from dreamer_linked_to_world.xacro  | -->
<!-- |    EDITING THIS FILE BY HAND IS NOT RECOMMENDED                                 | -->
<!-- =================================================================================== -->
<robot name="dreamer" xmlns:controller="http://playerstage.sourceforge.net/gazebo/xmlschema/#controller" xmlns:interface="http://playerstage.sourceforge.net/gazebo/xmlschema/#interface" xmlns:joint="http://playerstage.sourceforge.net/gazebo/xmlschema/#slider" xmlns:sensor="http://playerstage.sourceforge.net/gazebo/xmlschema/#sensor" xmlns:xacro="http://ros.org/wiki/xacro">
  <!-- Gazebo uses model:// for the model path. -->
  <!-- RViz uses package:// for the model path. -->
  <!-- <property name="MESH" value="mid_res" /> -->
  <!-- Its seems that zero mass links are not kosher. I can't find any solid data, only suggestions from people
    as to what small but not too small should be for mass numbers.
    Until better evidence/experience says otherwise, we will use a mass that is ~0.1% * total_mass, and
    the inertia properties of a cylinder. Justification: Most of these virtual links are the rotor attached
    to gearing and any attachment structure.
     -->
  <!--Torso-->
  <!-- ensure that modelPath, MESH, TORSO are defined in parent xacro -->
  <!-- Arms -->
  <!-- ============================   Upper Arm   ============================ -->
  <!-- ============================   Forearm   ============================ -->
  <!-- for non-symmetric upper arm -->
  <!-- ============================   Upper Arm   ============================ -->
  <!-- ============================   Forearm   ============================ -->
  <!-- Meka Hand -->
  <!-- INERTIA MATRIX CHANGE BY POLAM, VALUE=0.0011100-->
  <!-- INERTIA MATRIX CHANGE BY POLAM, VALUE=0.0011100-->
  <!-- Meka Head -->
  <!-- INERTIA MATRIX CHANGE BY POLAM, VALUE=0.0011100-->
  <!-- Define various colors -->
  <material name="GreyA">
    <color rgba="0.3 0.3 0.3 1.0"/>
  </material>
  <material name="GreyB">
    <color rgba="0.5 0.5 0.5 1.0"/>
  </material>
  <material name="GreyC">
    <color rgba="0.7 0.7 0.7 1.0"/>
  </material>

  <material name="face_main">
    <color rgba="1.0 1.0 1.0 1.0"/>
  </material>
  <material name="hair_main">
    <color rgba="1.0 0.5 0.0 1.0"/>
  </material>

  <!-- Add Dreamer's torso and specify the height of the pan plate above the ground. -->
  <link name="panplate_link">
    <inertial>
      <mass value="8"/>
      <origin xyz="0 0 0.8"/>
      <inertia ixx=".8" ixy="0" ixz="0" iyy=".8" iyz="0" izz=".8"/>
    </inertial>
    <visual>
      <material name="GreyA"/>
      <origin rpy="0 0 0 " xyz="0 0 0.8"/>
      <geometry name="panplate_geom">
        <mesh filename="package://dreamer/models/dreamer/meka_description/meshes/optimized/T2R3/T2R3_TJ0_base.stl"/>
      </geometry>
    </visual>
    <collision>
      <origin rpy="0.0 0.0 0.0 " xyz="0 0 0.8"/>
      <geometry name="base_collision_geom">
        <mesh filename="package://dreamer/models/dreamer/meka_description/meshes/low_res/T2R3/T2R3_TJ0_base.stl"/>
      </geometry>
    </collision>
  </link>
  <joint name="torso_yaw" type="fixed">
    <axis xyz="0 0 1"/>
    <origin rpy="0 0 0" xyz="0 0 0.9678"/>
    <parent link="panplate_link"/>
    <child link="torso_yaw_link"/>
    <limit effort="100" lower="-1.57079632679" upper="1.57079632679" velocity="0.436332312999"/>
    <dynamics damping="1.0"/>
  </joint>
  <link name="torso_yaw_link">
    <inertial>
      <mass value="4.411"/>
      <origin xyz="0.00011774 0.0038073 -0.0522753"/>
      <inertia ixx="0.026360" ixy="-0.0000024" ixz="-0.0000508" iyy="0.0134266" iyz="0.0006839" izz="0.0229879"/>
    </inertial>
    <visual>
      <material name="GreyC"/>
      <origin rpy="0 0 0 " xyz="0 0 0"/>
      <geometry name="torso_geom">
        <mesh filename="package://dreamer/models/dreamer/meka_description/meshes/optimized/T2R3/T2R3_TJ1_pan.stl"/>
      </geometry>
    </visual>
    <collision>
      <origin rpy="0.0 0.0 0.0 " xyz="0 0 0"/>
      <geometry name="torso_collision_geom">
        <mesh filename="package://dreamer/models/dreamer/meka_description/meshes/low_res/T2R3/T2R3_TJ1_pan.stl"/>
      </geometry>
    </collision>
  </link>
  <joint name="torso_lower_pitch" type="revolute">
    <axis xyz="0 1 0"/>
    <origin rpy="0 0 0" xyz="0 0 0"/>
    <parent link="torso_yaw_link"/>
    <child link="torso_lower_pitch_link"/>
    <limit effort="200" lower="-0.366519142919" upper="0.872664625997" velocity="0.174532925199"/>
    <dynamics damping="1.0"/>
  </joint>
  <link name="torso_lower_pitch_link">
    <inertial>
      <mass value="4.934"/>
      <origin xyz="0.001179 -0.002993 0.046259"/>
      <inertia ixx="0.041106" ixy="0.000135" ixz="0.000505" iyy="0.026009" iyz="0.002396" izz="0.025902"/>
    </inertial>
    <visual>
      <material name="GreyB"/>
      <origin rpy="0 0 0" xyz="0 0 0"/>
      <geometry name="mid_geom">
        <mesh filename="package://dreamer/models/dreamer/meka_description/meshes/optimized/T2R3/T2R3_TJ2.stl"/>
      </geometry>
    </visual>
    <collision>
      <origin rpy="0.0 0.0 0.0 " xyz="0 0 0"/>
      <geometry name="mid_collision_geom">
        <mesh filename="package://dreamer/models/dreamer/meka_description/meshes/low_res/T2R3/T2R3_TJ2.stl"/>
      </geometry>
    </collision>
  </link>
  <joint name="torso_upper_pitch" type="revolute">
    <axis xyz="0 1 0"/>
    <origin rpy="0 0 0" xyz="0 0 0.1397"/>
    <parent link="torso_lower_pitch_link"/>
    <child link="torso_upper_pitch_link"/>
    <limit effort="200" lower="-0.366519142919" upper="0.872664625997" velocity="0.174532925199"/>
    <dynamics damping="1.0"/>
  </joint>
  <!-- torso with motors, bottom pullies, and neck mount -->
  <link name="torso_upper_pitch_link">
    <inertial>
      <mass value="6.534"/>
      <origin xyz="0.008700 0.011470 0.129740"/>
      <inertia ixx="0.069760" ixy="-0.000400" ixz="0.001300" iyy="0.048010" iyz="0.005100" izz="0.040590"/>
    </inertial>
    <visual>
      <material name="GreyC"/>
      <origin rpy="0 0 0" xyz="0 0 0"/>
      <geometry name="upper_geom">
        <mesh filename="package://dreamer/models/dreamer/meka_description/meshes/optimized/T2R3/T2R3_TJ3_chest_waist_neck.stl"/>
      </geometry>
    </visual>
    <collision>
      <origin rpy="0.0 0.0 0.0 " xyz="0 0 0"/>
      <geometry name="upper_collision_geom">
        <mesh filename="package://dreamer/models/dreamer/meka_description/meshes/low_res/T2R3/T2R3_TJ3_chest_waist_neck.stl"/>
      </geometry>
    </collision>
  </link>
  <!-- Add left and right arms. -->
  <!-- Shoulder pan -->
  <joint name="right_shoulder_extensor" type="revolute">
    <axis xyz="0 -1 0"/>
    <origin rpy="0 0 0" xyz="0.0 -0.18465 0.2337"/>
    <!-- transform from parent link to this joint frame -->
    <parent link="torso_upper_pitch_link"/>
    <child link="right_shoulder_extensor_link"/>
    <limit effort="40" lower="-1.3962634016" upper="3.49065850399" velocity="0.523598775598"/>
    <dynamics damping="1.0"/>
  </joint>
  <link name="right_shoulder_extensor_link">
    <inertial>
      <mass value="2.0310"/>
      <origin xyz="-0.010946 0.025127 0.000022"/>
      <inertia ixx="0.003461" ixy="0.000428" ixz="0.000002" iyy="0.003097" iyz="0.000000" izz="0.005416"/>
    </inertial>
    <visual>
      <material name="GreyA"/>
      <origin rpy="0 0 0 " xyz="0 0 0"/>
      <geometry name="r_shoulder_geom">
        <mesh filename="package://dreamer/models/dreamer/meka_description/meshes/optimized/A2R3/A2R3_RT1_shoulderRoll.stl"/>
      </geometry>
    </visual>
    <collision>
      <origin rpy="0.0 0.0 0.0 " xyz="0 0 0"/>
      <geometry name="r_shoulder_collision_geom">
        <mesh filename="package://dreamer/models/dreamer/meka_description/meshes/low_res/A2R3/A2R3_RT1_shoulderRoll.stl"/>
      </geometry>
    </collision>
  </link>
  <joint name="right_shoulder_abductor" type="revolute">
    <axis xyz="-1 0 0"/>
    <limit effort="40" lower="-0.418879020479" upper="2.61799387799" velocity="0.523598775598"/>
    <origin rpy="0 0 0" xyz="0 0 0"/>
    <parent link="right_shoulder_extensor_link"/>
    <child link="right_shoulder_abductor_link"/>
    <dynamics damping="1.0"/>
  </joint>
  <link name="right_shoulder_abductor_link">
    <inertial>
      <mass value="0.566"/>
      <origin xyz="0.000944 -0.026331 -0.043257"/>
      <inertia ixx="0.000754" ixy="0.000015" ixz="0.000014" iyy="0.000921" iyz="0.000142" izz="0.000834"/>
    </inertial>
    <visual>
      <material name="GreyB"/>
      <origin rpy="0 0 0 " xyz="0 0 0"/>
      <geometry name="right_shoulder_abductor_link">
        <mesh filename="package://dreamer/models/dreamer/meka_description/meshes/optimized/A2R3/A2R3_RT2_shoulderPitch.stl"/>
      </geometry>
    </visual>
    <collision>
      <origin rpy="0.0 0.0 0.0 " xyz="0 0 0"/>
      <geometry name="right_shoulder_abductor_link_collision">
        <mesh filename="package://dreamer/models/dreamer/meka_description/meshes/low_res/A2R3/A2R3_RT2_shoulderPitch.stl"/>
      </geometry>
    </collision>
  </link>
  <joint name="right_shoulder_rotator" type="revolute">
    <axis xyz="0 0 -1"/>
    <origin rpy="0 0 0" xyz="0 -0.03175 -0.27857"/>
    <parent link="right_shoulder_abductor_link"/>
    <child link="right_shoulder_rotator_link"/>
    <limit effort="20" lower="-1.4835298642" upper="1.4835298642" velocity="0.872664625997"/>
    <dynamics damping="1.0"/>
  </joint>
  <link name="right_shoulder_rotator_link">
    <inertial>
      <mass value="2.296"/>
      <origin xyz="-0.005767 0.084539 0.001385"/>
      <inertia ixx="0.013031" ixy="-0.000564" ixz="-0.000077" iyy="0.002070" iyz="0.000162" izz="0.013173"/>
    </inertial>
    <visual>
      <material name="GreyC"/>
      <origin rpy="0 0 0 " xyz="0 0 0"/>
      <geometry name="right_shoulder_rotator_link_geom">
        <mesh filename="package://dreamer/models/dreamer/meka_description/meshes/optimized/A2R3/A2R3_RT3_bicep.stl"/>
      </geometry>
    </visual>
    <collision>
      <origin rpy="0.0 0.0 0.0 " xyz="0 0 0"/>
      <geometry name="right_shoulder_rotator_link_geom_collision">
        <mesh filename="package://dreamer/models/dreamer/meka_description/meshes/low_res/A2R3/A2R3_RT3_bicep.stl"/>
      </geometry>
    </collision>
  </link>
  <joint name="right_elbow" type="revolute">
    <axis xyz="0 -1 0"/>
    <origin rpy="0 0 0" xyz="0.00502 0  0"/>
    <parent link="right_shoulder_rotator_link"/>
    <child link="right_elbow_link"/>
    <limit effort="20" lower="-0.00486908464063" upper="2.31810267927" velocity="0.872664625997"/>
    <!-- <dynamics damping="10.0" /> -->
    <dynamics damping="1.0"/>
    <!-- Changed by liang to allow elbow to bend in simulation -->
  </joint>
  <link name="right_elbow_link">
    <inertial>
      <mass value="0.223"/>
      <origin xyz="-0.000002 0.000278 -0.026124"/>
      <inertia ixx="0.000470" ixy="0.000000" ixz="0.000000" iyy="0.000233" iyz="0.000019" izz="0.000425"/>
    </inertial>
    <visual>
      <material name="GreyA"/>
      <origin rpy="0 0 0 " xyz="0 0 0"/>
      <geometry name="right_elbow_link_geom">
        <mesh filename="package://dreamer/models/dreamer/meka_description/meshes/optimized/A2R3/A2R3_RT4_elbow.stl"/>
      </geometry>
    </visual>
    <collision>
      <origin rpy="0.0 0.0 0.0 " xyz="0 0 0"/>
      <geometry name="right_elbow_link_collision">
        <mesh filename="package://dreamer/models/dreamer/meka_description/meshes/low_res/A2R3/A2R3_RT4_elbow.stl"/>
      </geometry>
    </collision>
  </link>
  <joint name="right_wrist_rotator" type="revolute">
    <axis xyz="0 0 -1"/>
    <limit effort="4" lower="-0.862192650485" upper="4.00378530407" velocity="2.61799387799"/>
    <origin rpy="0 0 0" xyz="0 0 -0.27747"/>
    <parent link="right_elbow_link"/>
    <child link="right_wrist_rotator_link"/>
    <dynamics damping="1.0"/>
  </joint>
  <link name="right_wrist_rotator_link">
    <inertial>
      <mass value="1.468"/>
      <origin xyz="-0.004404 0.000124 0.130931"/>
      <inertia ixx="0.006099" ixy="0.000004" ixz="-0.000043" iyy="0.006120" iyz="0.000015" izz="0.001179"/>
    </inertial>
    <visual>
      <material name="GreyC"/>
      <origin rpy="0 0 0 " xyz="0 0 0"/>
      <geometry name="right_wrist_rotator_link_geom">
        <mesh filename="package://dreamer/models/dreamer/meka_description/meshes/optimized/A2R3/A2R3_T5_forearmRoll.stl"/>
      </geometry>
    </visual>
    <collision>
      <origin rpy="0.0 0.0 0.0 " xyz="0 0 0"/>
      <geometry name="right_wrist_rotator_link_collision">
        <mesh filename="package://dreamer/models/dreamer/meka_description/meshes/low_res/A2R3/A2R3_T5_forearmRoll.stl"/>
      </geometry>
    </collision>
  </link>
  <joint name="right_wrist_pitch" type="revolute">
    <dynamics damping="1.0"/>
    <axis xyz="0 -1 0"/>
    <origin rpy="0 0 0" xyz="0 0 0"/>
    <parent link="right_wrist_rotator_link"/>
    <child link="right_wrist_pitch_link"/>
    <limit effort="8" lower="-1.02677719895" upper="1.02677719895" velocity="0.698131700798"/>
  </joint>
  <link name="right_wrist_pitch_link">
    <inertial>
      <mass value="0.278"/>
      <origin xyz="0.00008 0.00163 0.00123"/>
      <inertia ixx="0.00013" ixy="0" ixz="0" iyy="0.00014" iyz="0" izz="0.0009"/>
    </inertial>
    <visual>
      <material name="GreyB"/>
      <origin rpy="0 0 0 " xyz="0 0 0"/>
      <geometry name="right_wrist_pitch_link_geom">
        <mesh filename="package://dreamer/models/dreamer/meka_description/meshes/optimized/A2R3/A2R3_T6_wristDiff.stl"/>
      </geometry>
    </visual>
    <collision>
      <origin rpy="0.0 0.0 0.0 " xyz="0 0 0"/>
      <geometry name="right_wrist_pitch_link_collision">
        <box size="0.01 0.01 0.01"/>
      </geometry>
    </collision>
  </link>
  <joint name="right_wrist_yaw" type="revolute">
    <axis xyz="-1 0 0"/>
    <limit effort="8" lower="-1.0471975512" upper="1.0471975512" velocity="0.698131700798"/>
    <origin rpy="0 0 0" xyz="0 0 0"/>
    <parent link="right_wrist_pitch_link"/>
    <child link="right_wrist_yaw_link"/>
    <dynamics damping="1.0"/>
  </joint>
  <link name="right_wrist_yaw_link">
    <inertial>
      <mass value="0.093"/>
      <origin xyz="-0.00286  -0.00207 -0.10657"/>
      <inertia ixx="0.00485" ixy="0" ixz="0" iyy="0.00508" iyz="0" izz="0.00081"/>
    </inertial>
    <visual>
      <material name="GreyA"/>
      <origin rpy="0 0 0 " xyz="0 0 0"/>
      <geometry name="right_wrist_yaw_link_geom">
        <mesh filename="package://dreamer/models/dreamer/meka_description/meshes/optimized/A2R3/A2R3_T7_wristYaw.stl"/>
      </geometry>
    </visual>
    <collision>
      <origin rpy="0.0 0.0 0.0 " xyz="0 0 0"/>
      <geometry name="right_wrist_yaw_link_collision">
        <mesh filename="package://dreamer/models/dreamer/meka_description/meshes/low_res/A2R3/A2R3_T7_wristYaw.stl"/>
      </geometry>
    </collision>
  </link>
  <!-- Shoulder pan -->
  <joint name="left_shoulder_extensor" type="revolute">
    <axis xyz="0 -1 0"/>
    <origin rpy="0 0 0" xyz="0.0 0.18465 0.2337"/>
    <!-- transform from parent link to this joint frame -->
    <parent link="torso_upper_pitch_link"/>
    <child link="left_shoulder_extensor_link"/>
    <limit effort="40" lower="-1.3962634016" upper="3.49065850399" velocity="0.523598775598"/>
    <dynamics damping="1.0"/>
  </joint>
  <link name="left_shoulder_extensor_link">
    <inertial>
      <mass value="2.0310"/>
      <origin xyz="-0.010946 -0.025127 0.000022"/>
      <inertia ixx="0.003461" ixy="0.000428" ixz="0.000002" iyy="0.003097" iyz="0.000000" izz="0.005416"/>
    </inertial>
    <visual>
      <material name="GreyA"/>
      <origin rpy="3.14159265359 0 0 " xyz="0 0 0"/>
      <geometry name="l_shoulder_geom">
        <mesh filename="package://dreamer/models/dreamer/meka_description/meshes/optimized/A2R3/A2R3_RT1_shoulderRoll.stl"/>
      </geometry>
    </visual>
    <collision>
      <origin rpy="3.14159265359 0.0 0.0 " xyz="0 0 0"/>
      <geometry name="r_shoulder_collision_geom">
        <mesh filename="package://dreamer/models/dreamer/meka_description/meshes/low_res/A2R3/A2R3_RT1_shoulderRoll.stl"/>
      </geometry>
    </collision>
  </link>
  <joint name="left_shoulder_abductor" type="revolute">
    <axis xyz="-1 0 0"/>
    <limit effort="40" lower="-0.418879020479" upper="2.61799387799" velocity="0.523598775598"/>
    <origin rpy="0 0 3.14159265359" xyz="0 0 0"/>
    <parent link="left_shoulder_extensor_link"/>
    <child link="left_shoulder_abductor_link"/>
    <dynamics damping="1.0"/>
  </joint>
  <link name="left_shoulder_abductor_link">
    <inertial>
      <mass value="0.566"/>
      <origin xyz="-0.000944 -0.026331 -0.043257"/>
      <inertia ixx="0.000754" ixy="0.000015" ixz="0.000014" iyy="0.000921" iyz="0.000142" izz="0.000834"/>
    </inertial>
    <visual>
      <material name="GreyB"/>
      <origin rpy="0 0 0 " xyz="0 0 0"/>
      <geometry name="left_shoulder_abductor_link">
        <mesh filename="package://dreamer/models/dreamer/meka_description/meshes/optimized/A2R3/A2R3_RT2_shoulderPitch.stl"/>
      </geometry>
    </visual>
    <collision>
      <origin rpy="0.0 0.0 0.0 " xyz="0 0 0"/>
      <geometry name="left_shoulder_abductor_link_collision">
        <mesh filename="package://dreamer/models/dreamer/meka_description/meshes/low_res/A2R3/A2R3_RT2_shoulderPitch.stl"/>
      </geometry>
    </collision>
  </link>
  <joint name="left_shoulder_rotator" type="revolute">
    <axis xyz="0 0 1"/>
    <origin rpy="0 0 3.14159265359" xyz="0 -0.03175 -0.27857"/>
    <parent link="left_shoulder_abductor_link"/>
    <child link="left_shoulder_rotator_link"/>
    <limit effort="20" lower="-1.4835298642" upper="1.4835298642" velocity="0.872664625997"/>
    <dynamics damping="1.0"/>
  </joint>
  <link name="left_shoulder_rotator_link">
    <inertial>
      <mass value="2.296"/>
      <origin xyz="-0.005767 0.084539 0.001385"/>
      <inertia ixx="0.013031" ixy="-0.000564" ixz="-0.000077" iyy="0.002070" iyz="0.000162" izz="0.013173"/>
    </inertial>
    <visual>
      <material name="GreyC"/>
      <origin rpy="0 0 0 " xyz="0 0 0"/>
      <geometry name="left_shoulder_rotator_link_geom">
        <mesh filename="package://dreamer/models/dreamer/meka_description/meshes/optimized/A2R3/A2R3_RT3_bicep.stl"/>
      </geometry>
    </visual>
    <collision>
      <origin rpy="0.0 0.0 0.0 " xyz="0 0 0"/>
      <geometry name="left_shoulder_rotator_link_geom_collision">
        <mesh filename="package://dreamer/models/dreamer/meka_description/meshes/low_res/A2R3/A2R3_RT3_bicep.stl"/>
      </geometry>
    </collision>
  </link>
  <joint name="left_elbow" type="revolute">
    <axis xyz="0 1 0"/>
    <origin rpy="0 0 3.14159265359" xyz="0.00502 0  0"/>
    <parent link="left_shoulder_rotator_link"/>
    <child link="left_elbow_link"/>
    <limit effort="20" lower="-0.00486908464063" upper="2.31810267927" velocity="0.872664625997"/>
    <dynamics damping="1.0"/>
    <!-- Changed by liang to allow elbow to bend in simulation -->
  </joint>
  <link name="left_elbow_link">
    <inertial>
      <mass value="0.223"/>
      <origin xyz="0.000002 -0.000278 -0.026124"/>
      <inertia ixx="0.000470" ixy="0.000000" ixz="0.000000" iyy="0.000233" iyz="0.000019" izz="0.000425"/>
    </inertial>
    <visual>
      <material name="GreyA"/>
      <origin rpy="0 0 0 " xyz="0 0 0"/>
      <geometry name="left_elbow_link_geom">
        <mesh filename="package://dreamer/models/dreamer/meka_description/meshes/optimized/A2R3/A2R3_RT4_elbow.stl"/>
      </geometry>
    </visual>
    <collision>
      <origin rpy="0.0 0.0 0.0 " xyz="0 0 0"/>
      <geometry name="left_elbow_link_collision">
        <mesh filename="package://dreamer/models/dreamer/meka_description/meshes/low_res/A2R3/A2R3_RT4_elbow.stl"/>
      </geometry>
    </collision>
  </link>
  <joint name="left_wrist_rotator" type="revolute">
    <axis xyz="0 0 1"/>
    <limit effort="4" lower="-0.862192650485" upper="4.00378530407" velocity="2.61799387799"/>
    <origin rpy="0 0 3.14159265359" xyz="0 0 -0.27747"/>
    <parent link="left_elbow_link"/>
    <child link="left_wrist_rotator_link"/>
    <dynamics damping="1.0"/>
  </joint>
  <link name="left_wrist_rotator_link">
    <inertial>
      <mass value="1.468"/>
      <origin xyz="-0.004404 0.000124 0.130931"/>
      <inertia ixx="0.006099" ixy="0.000004" ixz="-0.000043" iyy="0.006120" iyz="0.000015" izz="0.001179"/>
    </inertial>
    <visual>
      <material name="GreyC"/>
      <origin rpy="0 0 0 " xyz="0 0 0"/>
      <geometry name="left_wrist_rotator_link_geom">
        <mesh filename="package://dreamer/models/dreamer/meka_description/meshes/optimized/A2R3/A2R3_T5_forearmRoll.stl"/>
      </geometry>
    </visual>
    <collision>
      <origin rpy="0.0 0.0 0.0 " xyz="0 0 0"/>
      <geometry name="left_wrist_rotator_link_collision">
        <mesh filename="package://dreamer/models/dreamer/meka_description/meshes/low_res/A2R3/A2R3_T5_forearmRoll.stl"/>
      </geometry>
    </collision>
  </link>
  <joint name="left_wrist_pitch" type="revolute">
    <dynamics damping="1.0"/>
    <axis xyz="0 -1 0"/>
    <origin rpy="0 0 0" xyz="0 0 0"/>
    <parent link="left_wrist_rotator_link"/>
    <child link="left_wrist_pitch_link"/>
    <limit effort="8" lower="-1.02677719895" upper="1.02677719895" velocity="0.698131700798"/>
  </joint>
  <link name="left_wrist_pitch_link">
    <inertial>
      <mass value="0.278"/>
      <origin xyz="0.00008 0.00163 0.00123"/>
      <inertia ixx="0.00013" ixy="0" ixz="0" iyy="0.00014" iyz="0" izz="0.0009"/>
    </inertial>
    <visual>
      <material name="GreyB"/>
      <origin rpy="0 0 0" xyz="0 0 0"/>
      <geometry name="left_wrist_pitch_link_geom">
        <mesh filename="package://dreamer/models/dreamer/meka_description/meshes/optimized/A2R3/A2R3_T6_wristDiff.stl"/>
      </geometry>
    </visual>
    <collision>
      <origin rpy="0.0 0.0 0.0" xyz="0 0 0"/>
      <geometry name="left_wrist_pitch_link_collision">
        <box size="0.01 0.01 0.01"/>
      </geometry>
    </collision>
  </link>
  <joint name="left_wrist_yaw" type="revolute">
    <axis xyz="1 0 0"/>
    <limit effort="8" lower="-1.0471975512" upper="1.0471975512" velocity="0.698131700798"/>
    <origin rpy="0 0 0" xyz="0 0 0"/>
    <parent link="left_wrist_pitch_link"/>
    <child link="left_wrist_yaw_link"/>
    <dynamics damping="1.0"/>
  </joint>
  <link name="left_wrist_yaw_link">
    <inertial>
      <mass value="0.093"/>
      <origin xyz="-0.00286  -0.00207 -0.10657"/>
      <inertia ixx="0.00485" ixy="0" ixz="0" iyy="0.00508" iyz="0" izz="0.00081"/>
    </inertial>
    <visual>
      <material name="GreyA"/>
      <origin rpy="0 0 0" xyz="0 0 0"/>
      <geometry name="left_wrist_yaw_link_geom">
        <mesh filename="package://dreamer/models/dreamer/meka_description/meshes/optimized/A2R3/A2R3_T7_wristYaw.stl"/>
      </geometry>
    </visual>
    <collision>
      <origin rpy="0.0 0.0 0.0 " xyz="0 0 0"/>
      <geometry name="left_wrist_yaw_link_collision">
        <mesh filename="package://dreamer/models/dreamer/meka_description/meshes/low_res/A2R3/A2R3_T7_wristYaw.stl"/>
      </geometry>
    </collision>
  </link>
  <!-- Add the head. -->
  <joint name="lower_neck_pitch" type="revolute">
    <axis xyz="0 -1 0"/>
    <origin rpy="0 0 0" xyz="0.0 0.0 0.31155"/>
    <!-- transform from parent link to this joint frame -->
    <parent link="torso_upper_pitch_link"/>
    <child link="lower_neck_pitch_link"/>
    <limit effort="100" lower="-0.698131700798" upper="0.261799387799" velocity="0.349065850399"/>
  </joint>
  <link name="lower_neck_pitch_link">
    <inertial>
      <mass value="0.940"/>
      <origin xyz="0.000061 0.003310 0.028798"/>
      <inertia ixx="0.001395" ixy="-0.000000" ixz="-0.000000" iyy="0.001345" iyz="-0.000085" izz="0.000392"/>
    </inertial>
    <visual>
      <material name="GreyA"/>
      <origin rpy="0 0 0 " xyz="0 0 0"/>
      <geometry name="lower_neck_pitch_link_geom">
        <mesh filename="package://dreamer/models/dreamer/meka_description/meshes/optimized/S2R1/S2R1_SH1_neckTilt.stl"/>
      </geometry>
    </visual>
    <collision>
      <origin rpy="0.0 0.0 0.0 " xyz="0 0 0"/>
      <geometry name="lower_neck_pitch_link_geom_collison">
        <mesh filename="package://dreamer/models/dreamer/meka_description/meshes/low_res/S2R1/S2R1_SH1_neckTilt.stl"/>
      </geometry>
    </collision>
  </link>
  <joint name="upper_neck_yaw" type="revolute">
    <axis xyz="0 0 1"/>
    <limit effort="100" lower="-1.41230297742" upper="1.41214589779" velocity="1.308996939"/>
    <origin rpy="0 0 0" xyz="0 0 0.13849"/>
    <parent link="lower_neck_pitch_link"/>
    <child link="upper_neck_yaw_link"/>
  </joint>
  <link name="upper_neck_yaw_link">
    <inertial>
      <mass value="0.409"/>
      <origin xyz="0.0 0.0 0.0"/>
      <inertia ixx="0.0011100" ixy="0.0" ixz="0.0" iyy="0.0011100" iyz="0.0" izz="0.0011100"/>
    </inertial>
    <visual>
      <material name="GreyB"/>
      <origin rpy="0 0 0 " xyz="0 0 0"/>
      <geometry name="neck_roll_geom">
        <mesh filename="package://dreamer/models/dreamer/meka_description/meshes/optimized/S2R1/S2R1_SH2_neckRoll.stl"/>
      </geometry>
    </visual>
    <collision>
      <origin rpy="0.0 0.0 0.0 " xyz="0 0 0"/>
      <geometry name="S2R1_SH2_neckRoll_collision">
        <box size="0.01 0.01 0.01"/>
      </geometry>
    </collision>
  </link>
  <joint name="upper_neck_roll" type="revolute">
    <axis xyz="-1 0 0"/>
    <origin rpy="0 0 0" xyz="0 0 0"/>
    <parent link="upper_neck_yaw_link"/>
    <child link="upper_neck_roll_link"/>
    <limit effort="100" lower="-0.260752190248" upper="0.260752190248" velocity="0.872664625997"/>
  </joint>
  <link name="upper_neck_roll_link">
    <inertial>
      <mass value="0.496"/>
      <origin xyz="-0.010690 0.053982 0.000045"/>
      <inertia ixx="0.001094" ixy="0.000284" ixz="0.000000" iyy="0.000311" iyz="0.000000" izz="0.001222"/>
    </inertial>
    <visual>
      <material name="GreyC"/>
      <origin rpy="0 0 0 " xyz="0 0 0"/>
      <geometry name="S2R1_H3_neckYaw_geom">
        <mesh filename="package://dreamer/models/dreamer/meka_description/meshes/optimized/S2R1/S2R1_H3_neckYaw.stl"/>
      </geometry>
    </visual>
    <collision>
      <origin rpy="0.0 0.0 0.0 " xyz="0 0 0"/>
      <geometry name="S2R1_H3_neckYaw_collision">
        <box size="0.01 0.01 0.01"/>
      </geometry>
    </collision>
  </link>
  <joint name="upper_neck_pitch" type="revolute">
    <axis xyz="0 -1 0"/>
    <origin rpy="0 0 0" xyz="0 0 0"/>
    <parent link="upper_neck_roll_link"/>
    <child link="upper_neck_pitch_link"/>
    <limit effort="100" lower="-0.123429684701" upper="0.647028460299" velocity="0.872664625997"/>
  </joint>
  <link name="upper_neck_pitch_link">
    <inertial>
      <mass value="3.178"/>
      <origin xyz="0.034944 0.000563 0.058668"/>
      <inertia ixx="0.022924" ixy="-0.000034" ixz="-0.002929" iyy="0.021814" iyz="-0.000235" izz="0.026783"/>
    </inertial>
    <visual>
      <!-- <material name="GreyA"/> -->
      <material name="face_main"/>      
      <origin rpy="0 0 0 " xyz="0 0 0"/>
      <geometry name="upper_pitch_link_geom">
        <mesh filename="package://dreamer/models/dreamer/meka_description/meshes/optimized/S2R1/S2R1_H4_UTA_head.stl"/>
      </geometry>
    </visual>
    <collision>
      <origin rpy="0.0 0.0 0.0 " xyz="0 0 0"/>
      <geometry name="upper_pitch_link_collision">
        <mesh filename="package://dreamer/models/dreamer/meka_description/meshes/low_res/S2R1/S2R1_H4_UTA_head.stl"/>
      </geometry>
    </collision>
  </link>
  <joint name="eye_pitch" type="revolute">
    <axis xyz="0 -1 0"/>
    <limit effort="100" lower="-0.610690705273" upper="0.610690705273" velocity="27.9252680319"/>
    <origin rpy="0 0 0" xyz="0.12508 0 0"/>
    <parent link="upper_neck_pitch_link"/>
    <child link="eye_pitch_link"/>
  </joint>
  <link name="eye_pitch_link">
    <!--Added by Gwen; no inertial data provided by Meka-->
    <inertial>
      <mass value="0.00001"/>
      <origin xyz="0.00000 0.0000 0.0000"/>
      <inertia ixx="0.0011100" ixy="0.0" ixz="0.0" iyy="0.0011100" iyz="0.0" izz="0.0011100"/>
    </inertial>
    <visual>
      <material name="GreyC"/>
      <origin rpy="0 0 0 " xyz="0 0 0"/>
      <geometry name="eye_pitch_link_geom">
        <mesh filename="package://dreamer/models/dreamer/meka_description/meshes/optimized/S2R1/S2R1_SH5_eyeTilt.stl"/>
      </geometry>
    </visual>
    <collision>
      <origin rpy="0.0 0.0 0.0 " xyz="0 0 0"/>
      <geometry name="eye_pitch_link_collision">
        <box size="0.01 0.01 0.01"/>
      </geometry>
    </collision>
  </link>
  <joint name="right_eye_yaw" type="revolute">
    <axis xyz="0 0 1"/>
    <limit effort="100" lower="-0.597077137107" upper="0.597129496985" velocity="27.9252680319"/>
    <origin rpy="0 0 0" xyz="0 -0.053 0"/>
    <parent link="eye_pitch_link"/>
    <child link="right_eye_yaw_link"/>
  </joint>
  <link name="right_eye_yaw_link">
    <!--Added by Gwen; no inertial data provided by Meka-->
    <inertial>
      <mass value="0.00001"/>
      <origin xyz="0.00000 0.0000 0.0000"/>
      <inertia ixx="0.0011100" ixy="0.0" ixz="0.0" iyy="0.0011100" iyz="0.0" izz="0.0011100"/>
    </inertial>
    <visual>
      <material name="GreyC"/>
      <origin rpy="0 0 0 " xyz="0 0 0"/>
      <geometry name="right_eye_yaw_link_geom">
        <mesh filename="package://dreamer/models/dreamer/meka_description/meshes/optimized/S2R1/S2R1_eye.stl"/>
      </geometry>
    </visual>
    <collision>
      <origin rpy="0.0 0.0 0.0 " xyz="0 0 0"/>
      <geometry name="right_eye_yaw_link_collision">
        <mesh filename="package://dreamer/models/dreamer/meka_description/meshes/low_res/S2R1/S2R1_eye.stl"/>
      </geometry>
    </collision>
  </link>
  <joint name="left_eye_yaw" type="revolute">
    <axis xyz="0 0 1"/>
    <limit effort="100" lower="-0.6129596333" upper="0.613046899763" velocity="27.9252680319"/>
    <origin rpy="0 0 0" xyz="0 0.053 0"/>
    <parent link="eye_pitch_link"/>
    <child link="left_eye_yaw_link"/>
  </joint>
  <link name="left_eye_yaw_link">
    <!--Added by Gwen; no inertial data provided by Meka-->
    <inertial>
      <mass value="0.00001"/>
      <origin xyz="0.00000 0.0000 0.0000"/>
      <inertia ixx="0.0011100" ixy="0.0" ixz="0.0" iyy="0.0011100" iyz="0.0" izz="0.0011100"/>
    </inertial>
    <visual>
      <material name="GreyC"/>
      <origin rpy="0 0 0 " xyz="0 0 0"/>
      <geometry name="left_eye_yaw_link_geom">
        <mesh filename="package://dreamer/models/dreamer/meka_description/meshes/optimized/S2R1/S2R1_eye.stl"/>
      </geometry>
    </visual>
    <collision>
      <origin rpy="0.0 0.0 0.0 " xyz="0 0 0"/>
      <geometry name="left_eye_yaw_link_collision">
        <mesh filename="package://dreamer/models/dreamer/meka_description/meshes/low_res/S2R1/S2R1_eye.stl"/>
      </geometry>
    </collision>
  </link>
  <!-- Add right hand. -->
  <joint name="palm_joint" type="fixed">
    <origin rpy="0 0 0" xyz="0 0 -0.04414"/>
    <parent link="right_wrist_yaw_link"/>
    <child link="palm"/>
  </joint>
  <link name="palm">
    <inertial>
      <mass value="0.5932"/>
      <!-- Matches mass used by UTA-WBC -->
      <!-- <mass value="0.663" /> -->
      <origin xyz="0.001459 0.001619 -0.051312"/>
      <inertia ixx="0.000873" ixy="0.000031" ixz="-0.000008" iyy="0.000597" iyz="0.000016" izz="0.000565"/>
    </inertial>
    <visual>
      <material name="GreyA"/>
      <origin rpy="0 0 0 " xyz="0 0 0"/>
      <geometry name="palm_geom">
        <mesh filename="package://dreamer/models/dreamer/meka_description/meshes/optimized/H2R3/H2R3_RT8_palm_right.stl"/>
      </geometry>
    </visual>
    <collision>
      <origin rpy="0.0 0.0 0.0 " xyz="0 0 0"/>
      <geometry name="palm_collision">
        <mesh filename="package://dreamer/models/dreamer/meka_description/meshes/low_res/H2R3/H2R3_RT8_palm_right.stl"/>
      </geometry>
    </collision>
  </link>
  <gazebo reference="palm">
    <mu1>1</mu1>
    <mu2>1</mu2>
  </gazebo>
  <!-- Start Thumb -->
  <joint name="right_thumb_cmc" type="revolute">
    <axis xyz="0 0 -1"/>
    <origin rpy="0 0 0" xyz="-0.02 0.028 -0.03"/>
    <parent link="palm"/>
    <child link="right_thumb_cmc_link"/>
    <limit effort="100" lower="-0.698131700798" upper="1.57079632679" velocity="0.349065850399"/>
  </joint>
  <link name="right_thumb_cmc_link">
    <inertial>
      <mass value="0.0117"/>
      <origin rpy="0 0 0" xyz="0 0 0"/>
      <inertia ixx="1.44698151e-06" ixy="0.0" ixz="0.0" iyy="2.29292115e-06" iyz="0.0" izz="1.47773964e-06"/>
    </inertial>
    <visual>
      <geometry>
        <mesh filename="package://dreamer/models/dreamer/meka_description/meshes/optimized/H2R3/H2R3_RJ0_thumb_abductlink.stl" scale="1 1 1"/>
      </geometry>
      <origin rpy="0 0 0" xyz="0 0 0"/>
      <!-- <origin rpy="${origin_rpy}" xyz="${origin_xyz}"/> -->
      <material name="GreyA"/>
    </visual>
    <collision>
      <geometry>
        <mesh filename="package://dreamer/models/dreamer/meka_description/meshes/low_res/H2R3/H2R3_RJ0_thumb_abductlink.stl"/>
      </geometry>
      <origin rpy="0 0 0" xyz="0 0 0"/>
    </collision>
  </link>
  <gazebo reference="right_thumb_cmc_link">
    <mu1>1</mu1>
    <mu2>1</mu2>
  </gazebo>
  <joint name="right_thumb_mcp" type="revolute">
    <axis xyz="0 -1 0"/>
    <limit effort="100" lower="-1.41230297742" upper="1.41214589779" velocity="1.308996939"/>
    <origin rpy="0 0 0" xyz="-0.018 0 0"/>
    <parent link="right_thumb_cmc_link"/>
    <child link="right_thumb_mcp_link"/>
  </joint>
  <link name="right_thumb_mcp_link">
    <inertial>
      <mass value="0.0344"/>
      <origin xyz="0.0 0.0 0.0"/>
      <inertia ixx="0.0011100" ixy="0.0" ixz="0.0" iyy="0.0011100" iyz="0.0" izz="0.0011100"/>
    </inertial>
    <visual>
      <material name="GreyB"/>
      <origin rpy="0 0 0 " xyz="0 0 0"/>
      <geometry name="right_thumb_mcp_link_geom">
        <mesh filename="package://dreamer/models/dreamer/meka_description/meshes/optimized/H2R3/H2R3_thumb_knuckle1.stl"/>
      </geometry>
    </visual>
    <collision>
      <origin rpy="0.0 0.0 0.0 " xyz="0 0 0"/>
      <geometry name="right_thumb_mcp_link_collision">
        <mesh filename="package://dreamer/models/dreamer/meka_description/meshes/low_res/H2R3/H2R3_thumb_knuckle1.stl"/>
      </geometry>
    </collision>
  </link>
  <gazebo reference="right_thumb_mcp_link">
    <mu1>1</mu1>
    <mu2>1</mu2>
  </gazebo>
  <joint name="right_thumb_ip" type="revolute">
    <axis xyz="0 -1 0"/>
    <origin rpy="0 0 0" xyz="-0.044 0 0"/>
    <parent link="right_thumb_mcp_link"/>
    <child link="right_thumb_ip_link"/>
    <limit effort="100" lower="-0.260752190248" upper="0.260752190248" velocity="0.872664625997"/>
  </joint>
  <link name="right_thumb_ip_link">
    <inertial>
      <mass value="0.01"/>
      <origin xyz="0.0 0.0 0.0"/>
      <inertia ixx="0.0011100" ixy="0.0" ixz="0.0" iyy="0.0011100" iyz="0.0" izz="0.0011100"/>
    </inertial>
    <visual>
      <material name="GreyC"/>
      <origin rpy="0 0 0 " xyz="0 0 0"/>
      <geometry name="thumb_knuckle2_geom">
        <mesh filename="package://dreamer/models/dreamer/meka_description/meshes/optimized/H2R3/H2R3_thumb_knuckle2.stl"/>
      </geometry>
    </visual>
    <collision>
      <origin rpy="0.0 0.0 0.0 " xyz="0 0 0"/>
      <geometry name="thumb_knuckle2_collision">
        <mesh filename="package://dreamer/models/dreamer/meka_description/meshes/low_res/H2R3/H2R3_thumb_knuckle2.stl"/>
      </geometry>
    </collision>
  </link>
  <gazebo reference="right_thumb_ip_link">
    <mu1>1</mu1>
    <mu2>1</mu2>
  </gazebo>
  <!-- Start Index Finger -->
  <joint name="right_pointer_finger_mcp" type="revolute">
    <axis xyz="0 1 0"/>
    <origin rpy="0 0 0" xyz="0 0.028 -0.101"/>
    <parent link="palm"/>
    <child link="right_pointer_finger_mcp_link"/>
    <limit effort="100" lower="-0.123429684701" upper="0.647028460299" velocity="0.872664625997"/>
  </joint>
  <link name="right_pointer_finger_mcp_link">
    <inertial>
      <mass value="0.01"/>
      <origin xyz="0.0 0.0 0.0"/>
      <inertia ixx="0.0011100" ixy="0.0" ixz="0.0" iyy="0.0011100" iyz="0.0" izz="0.0011100"/>
    </inertial>
    <visual>
      <material name="GreyA"/>
      <origin rpy="0 0 0 " xyz="0 0 0"/>
      <geometry name="right_pointer_finger_mcp_link_geom">
        <mesh filename="package://dreamer/models/dreamer/meka_description/meshes/optimized/H2R3/H2R3_finger_knuckle1.stl"/>
      </geometry>
    </visual>
    <collision>
      <origin rpy="0.0 0.0 0.0 " xyz="0 0 0"/>
      <geometry name="right_pointer_finger_mcp_link__collision">
        <mesh filename="package://dreamer/models/dreamer/meka_description/meshes/low_res/H2R3/H2R3_finger_knuckle1.stl"/>
      </geometry>
    </collision>
  </link>
  <gazebo reference="right_pointer_finger_mcp_link">
    <mu1>1</mu1>
    <mu2>1</mu2>
  </gazebo>
  <joint name="right_pointer_finger_pip" type="revolute">
    <axis xyz="0 1 0"/>
    <limit effort="100" lower="-0.610690705273" upper="0.610690705273" velocity="27.9252680319"/>
    <origin rpy="0 0 0" xyz="0 0 -0.044"/>
    <parent link="right_pointer_finger_mcp_link"/>
    <child link="right_pointer_finger_pip"/>
  </joint>
  <link name="right_pointer_finger_pip">
    <inertial>
      <mass value="0.0429"/>
      <origin xyz="0.0 0.0 0.0"/>
      <inertia ixx="0.0011100" ixy="0.0" ixz="0.0" iyy="0.0011100" iyz="0.0" izz="0.0011100"/>
    </inertial>
    <visual>
      <material name="GreyC"/>
      <origin rpy="0 0 0 " xyz="0 0 0"/>
      <geometry name="right_pointer_finger_pip_geom">
        <mesh filename="package://dreamer/models/dreamer/meka_description/meshes/optimized/H2R3/H2R3_finger_knuckle2.stl"/>
      </geometry>
    </visual>
    <collision>
      <origin rpy="0.0 0.0 0.0 " xyz="0 0 0"/>
      <geometry name="right_pointer_finger_pip_collision">
        <mesh filename="package://dreamer/models/dreamer/meka_description/meshes/low_res/H2R3/H2R3_finger_knuckle2.stl"/>
      </geometry>
    </collision>
  </link>
  <gazebo reference="right_pointer_finger_pip">
    <mu1>1</mu1>
    <mu2>1</mu2>
  </gazebo>
  <joint name="right_pointer_finger_dip" type="revolute">
    <axis xyz="0 1 0"/>
    <limit effort="100" lower="-0.597077137107" upper="0.597129496985" velocity="27.9252680319"/>
    <origin rpy="0 0 0" xyz="0 0 -0.032"/>
    <parent link="right_pointer_finger_pip"/>
    <child link="right_pointer_finger_dip_link"/>
  </joint>
  <link name="right_pointer_finger_dip_link">
    <inertial>
      <mass value="0.01"/>
      <origin xyz="0.0 0.0 0.0"/>
      <inertia ixx="0.0011100" ixy="0.0" ixz="0.0" iyy="0.0011100" iyz="0.0" izz="0.0011100"/>
    </inertial>
    <visual>
      <material name="GreyC"/>
      <origin rpy="0 0 0 " xyz="0 0 0"/>
      <geometry name="right_pointer_finger_dip_link_geom">
        <mesh filename="package://dreamer/models/dreamer/meka_description/meshes/optimized/H2R3/H2R3_finger_knuckle3.stl"/>
      </geometry>
    </visual>
    <collision>
      <origin rpy="0.0 0.0 0.0 " xyz="0 0 0"/>
      <geometry name="right_pointer_finger_dip_link_collision">
        <mesh filename="package://dreamer/models/dreamer/meka_description/meshes/low_res/H2R3/H2R3_finger_knuckle3.stl"/>
      </geometry>
    </collision>
  </link>
  <gazebo reference="right_pointer_finger_dip_link">
    <mu1>1</mu1>
    <mu2>1</mu2>
  </gazebo>
  <!-- Start Ring Finger -->
  <joint name="right_middle_finger_mcp" type="revolute">
    <axis xyz="0 1 0"/>
    <origin rpy="0 0 0" xyz="0 0 -0.101"/>
    <parent link="palm"/>
    <child link="right_middle_finger_mcp_link"/>
    <limit effort="100" lower="-0.123429684701" upper="0.647028460299" velocity="0.872664625997"/>
  </joint>
  <link name="right_middle_finger_mcp_link">
    <inertial>
      <mass value="0.01"/>
      <origin xyz="0.0 0.0 0.0"/>
      <inertia ixx="0.0011100" ixy="0.0" ixz="0.0" iyy="0.0011100" iyz="0.0" izz="0.0011100"/>
    </inertial>
    <visual>
      <material name="GreyA"/>
      <origin rpy="0 0 0 " xyz="0 0 0"/>
      <geometry name="right_middle_finger_mcp_link_geom">
        <mesh filename="package://dreamer/models/dreamer/meka_description/meshes/optimized/H2R3/H2R3_finger_knuckle1.stl"/>
      </geometry>
    </visual>
    <collision>
      <origin rpy="0.0 0.0 0.0 " xyz="0 0 0"/>
      <geometry name="right_middle_finger_mcp_link__collision">
        <mesh filename="package://dreamer/models/dreamer/meka_description/meshes/low_res/H2R3/H2R3_finger_knuckle1.stl"/>
      </geometry>
    </collision>
  </link>
  <gazebo reference="right_middle_finger_mcp_link">
    <mu1>1</mu1>
    <mu2>1</mu2>
  </gazebo>
  <joint name="right_middle_finger_pip" type="revolute">
    <axis xyz="0 1 0"/>
    <limit effort="100" lower="-0.610690705273" upper="0.610690705273" velocity="27.9252680319"/>
    <origin rpy="0 0 0" xyz="0 0 -0.044"/>
    <parent link="right_middle_finger_mcp_link"/>
    <child link="right_middle_finger_pip_link"/>
  </joint>
  <link name="right_middle_finger_pip_link">
    <inertial>
      <mass value="0.0429"/>
      <origin xyz="0.0 0.0 0.0"/>
      <inertia ixx="0.0011100" ixy="0.0" ixz="0.0" iyy="0.0011100" iyz="0.0" izz="0.0011100"/>
    </inertial>
    <visual>
      <material name="GreyC"/>
      <origin rpy="0 0 0 " xyz="0 0 0"/>
      <geometry name="right_middle_finger_pip_link_geom">
        <mesh filename="package://dreamer/models/dreamer/meka_description/meshes/optimized/H2R3/H2R3_finger_knuckle2.stl"/>
      </geometry>
    </visual>
    <collision>
      <origin rpy="0.0 0.0 0.0 " xyz="0 0 0"/>
      <geometry name="right_middle_finger_pip_link_collision">
        <mesh filename="package://dreamer/models/dreamer/meka_description/meshes/low_res/H2R3/H2R3_finger_knuckle2.stl"/>
      </geometry>
    </collision>
  </link>
  <gazebo reference="right_middle_finger_pip_link">
    <mu1>1</mu1>
    <mu2>1</mu2>
  </gazebo>
  <joint name="right_middle_finger_dip" type="revolute">
    <axis xyz="0 1 0"/>
    <limit effort="100" lower="-0.597077137107" upper="0.597129496985" velocity="27.9252680319"/>
    <origin rpy="0 0 0" xyz="0 0 -0.032"/>
    <parent link="right_middle_finger_pip_link"/>
    <child link="right_middle_finger_dip_link"/>
  </joint>
  <link name="right_middle_finger_dip_link">
    <inertial>
      <mass value="0.01"/>
      <origin xyz="0.0 0.0 0.0"/>
      <inertia ixx="0.0011100" ixy="0.0" ixz="0.0" iyy="0.0011100" iyz="0.0" izz="0.0011100"/>
    </inertial>
    <visual>
      <material name="GreyC"/>
      <origin rpy="0 0 0 " xyz="0 0 0"/>
      <geometry name="right_middle_finger_dip_link_geom">
        <mesh filename="package://dreamer/models/dreamer/meka_description/meshes/optimized/H2R3/H2R3_finger_knuckle3.stl"/>
      </geometry>
    </visual>
    <collision>
      <origin rpy="0.0 0.0 0.0 " xyz="0 0 0"/>
      <geometry name="right_middle_finger_dip_link_collision">
        <mesh filename="package://dreamer/models/dreamer/meka_description/meshes/low_res/H2R3/H2R3_finger_knuckle3.stl"/>
      </geometry>
    </collision>
  </link>
  <gazebo reference="right_middle_finger_dip_link">
    <mu1>1</mu1>
    <mu2>1</mu2>
  </gazebo>
  <!-- Start Pinky Finger -->
  <joint name="right_pinky_mcp" type="revolute">
    <axis xyz="0 1 0"/>
    <origin rpy="0 0 0" xyz="0 -0.028 -0.101"/>
    <parent link="palm"/>
    <child link="right_pinky_mcp"/>
    <limit effort="100" lower="-0.123429684701" upper="0.647028460299" velocity="0.872664625997"/>
  </joint>
  <link name="right_pinky_mcp">
    <inertial>
      <mass value="0.01"/>
      <origin xyz="0.0 0.0 0.0"/>
      <inertia ixx="0.0011100" ixy="0.0" ixz="0.0" iyy="0.0011100" iyz="0.0" izz="0.0011100"/>
    </inertial>
    <visual>
      <material name="GreyA"/>
      <origin rpy="0 0 0 " xyz="0 0 0"/>
      <geometry name="right_pinky_mcp_geom">
        <mesh filename="package://dreamer/models/dreamer/meka_description/meshes/optimized/H2R3/H2R3_finger_knuckle1.stl"/>
      </geometry>
    </visual>
    <collision>
      <origin rpy="0.0 0.0 0.0 " xyz="0 0 0"/>
      <geometry name="right_pinky_mcp__collision">
        <mesh filename="package://dreamer/models/dreamer/meka_description/meshes/low_res/H2R3/H2R3_finger_knuckle1.stl"/>
      </geometry>
    </collision>
  </link>
  <gazebo reference="right_pinky_mcp">
    <mu1>1</mu1>
    <mu2>1</mu2>
  </gazebo>
  <joint name="right_pinky_pip" type="revolute">
    <axis xyz="0 1 0"/>
    <limit effort="100" lower="-0.610690705273" upper="0.610690705273" velocity="27.9252680319"/>
    <origin rpy="0 0 0" xyz="0 0 -0.044"/>
    <parent link="right_pinky_mcp"/>
    <child link="right_pinky_pip"/>
  </joint>
  <link name="right_pinky_pip">
    <inertial>
      <mass value="0.0429"/>
      <origin xyz="0.0 0.0 0.0"/>
      <inertia ixx="0.0011100" ixy="0.0" ixz="0.0" iyy="0.0011100" iyz="0.0" izz="0.0011100"/>
    </inertial>
    <visual>
      <material name="GreyC"/>
      <origin rpy="0 0 0 " xyz="0 0 0"/>
      <geometry name="right_pinky_pip_geom">
        <mesh filename="package://dreamer/models/dreamer/meka_description/meshes/optimized/H2R3/H2R3_finger_knuckle2.stl"/>
      </geometry>
    </visual>
    <collision>
      <origin rpy="0.0 0.0 0.0 " xyz="0 0 0"/>
      <geometry name="right_pinky_pip_collision">
        <mesh filename="package://dreamer/models/dreamer/meka_description/meshes/low_res/H2R3/H2R3_finger_knuckle2.stl"/>
      </geometry>
    </collision>
  </link>
  <gazebo reference="right_pinky_pip">
    <mu1>1</mu1>
    <mu2>1</mu2>
  </gazebo>
  <joint name="right_pinky_dip" type="revolute">
    <axis xyz="0 1 0"/>
    <limit effort="100" lower="-0.597077137107" upper="0.597129496985" velocity="27.9252680319"/>
    <origin rpy="0 0 0" xyz="0 0 -0.032"/>
    <parent link="right_pinky_pip"/>
    <child link="right_pinky_dip_link"/>
  </joint>
  <link name="right_pinky_dip_link">
    <inertial>
      <mass value="0.01"/>
      <origin xyz="0.0 0.0 0.0"/>
      <inertia ixx="0.0011100" ixy="0.0" ixz="0.0" iyy="0.0011100" iyz="0.0" izz="0.0011100"/>
    </inertial>
    <visual>
      <material name="GreyC"/>
      <origin rpy="0 0 0 " xyz="0 0 0"/>
      <geometry name="right_pinky_dip_link_geom">
        <mesh filename="package://dreamer/models/dreamer/meka_description/meshes/optimized/H2R3/H2R3_finger_knuckle3.stl"/>
      </geometry>
    </visual>
    <collision>
      <origin rpy="0.0 0.0 0.0 " xyz="0 0 0"/>
      <geometry name="right_pinky_dip_link_collision">
        <mesh filename="package://dreamer/models/dreamer/meka_description/meshes/low_res/H2R3/H2R3_finger_knuckle3.stl"/>
      </geometry>
    </collision>
  </link>
  <gazebo reference="right_pinky_dip_link">
    <mu1>1</mu1>
    <mu2>1</mu2>
  </gazebo>
  <!--
    <m3_l_hand side="l" reflect="1" parent="left_wrist_yaw_link">
        <origin xyz="0.0 0.0 0.0" rpy="0 0 0" />
    </m3_l_hand>
    -->
  <!-- Add PR2 gripper onto end of left arm -->
  <!--Modify by POLAM-->
  <joint name="l_gripper_palm_joint" type="fixed">
    <origin rpy="1.57 1.57 0" xyz="0 0 0"/>
    <parent link="left_wrist_yaw_link"/>
    <child link="l_gripper_palm_link"/>
  </joint>
  <link name="l_gripper_palm_link">
    <inertial>
      <!-- <mass value="0.31047" /> -->
      <!-- This mass is used to match UTA-WBC's model -->
      <mass value="0.58007"/>
      <origin rpy="0 0 0" xyz="0.06623 0.00053 -0.00119"/>
      <inertia ixx="0.001" ixy="0.0" ixz="0.0" iyy="0.001" iyz="0.0" izz="0.001"/>
    </inertial>
    <visual>
      <origin rpy="0 0 0" xyz="0 0 0"/>
      <geometry>
        <mesh filename="package://dreamer/models/dreamer/meka_description/meshes/gripper_v0/gripper_palm.dae"/>
      </geometry>
      <material name="Red"/>
    </visual>
    <collision>
      <origin rpy="0 0 0" xyz="0 0 0"/>
      <geometry>
        <mesh filename="package://dreamer/models/dreamer/meka_description/meshes/gripper_v0/gripper_palm.stl"/>
      </geometry>
    </collision>
  </link>
  <joint name="l_gripper_led_joint" type="fixed">
    <!--  Need to check if we need a positive or negative Z term -->
    <origin xyz="0.0513 0.0 .0244"/>
    <parent link="l_gripper_palm_link"/>
    <child link="l_gripper_led_frame"/>
  </joint>
  <link name="l_gripper_led_frame"/>
  <joint name="l_gripper_motor_accelerometer_joint" type="fixed">
    <origin rpy="0 0 0" xyz="0 0 0"/>
    <parent link="l_gripper_palm_link"/>
    <child link="l_gripper_motor_accelerometer_link"/>
  </joint>
  <link name="l_gripper_motor_accelerometer_link">
    <inertial>
      <mass value="0.001"/>
      <origin rpy="0 0 0" xyz="0 0 0"/>
      <inertia ixx="0.001" ixy="0.0" ixz="0.0" iyy="0.001" iyz="0.0" izz="0.001"/>
    </inertial>
    <visual>
      <origin rpy="0 0 0" xyz="0 0 0"/>
      <geometry>
        <box size="0.001 0.001 0.001"/>
      </geometry>
    </visual>
    <collision>
      <origin rpy="0 0 0" xyz="0 0 0"/>
      <geometry>
        <box size="0.001 0.001 0.001"/>
      </geometry>
    </collision>
  </link>
  <joint name="l_gripper_tool_joint" type="fixed">
    <origin rpy="0 0 0" xyz="0.18 0 0"/>
    <parent link="l_gripper_palm_link"/>
    <child link="l_gripper_tool_frame"/>
  </joint>
  <link name="l_gripper_tool_frame"/>
  <!-- pr2 fingers macro -->
  <!-- Finger proximal digit -->
  <joint name="l_gripper_l_finger_joint" type="revolute">
    <axis xyz="0 0 1"/>
    <!-- limits on passive finger and finger top joints without
         transmission are not enforced by safety controllers.
         The lower/upper limits and are enforced in PR2 simulation and
         effort and velocity limits are ignored. This is also needed because
         these joints are declared revolute rather than continuous.-->
    <limit effort="1000.0" lower="0.0" upper="0.548" velocity="0.5"/>
    <dynamics damping="0.02"/>
    <origin rpy="0 0 0" xyz="0.07691 0.01 0"/>
    <parent link="l_gripper_palm_link"/>
    <child link="l_gripper_l_finger_link"/>
  </joint>
  <link name="l_gripper_l_finger_link">
    <inertial>
      <mass value="0.17126"/>
      <origin rpy="0 0 0" xyz="0.03598 0.01730 -0.00164"/>
      <inertia ixx="0.001" ixy="0.0" ixz="0.0" iyy="0.001" iyz="0.0" izz="0.001"/>
    </inertial>
    <visual>
      <origin rpy="0 0 0" xyz="0 0 0"/>
      <geometry>
        <mesh filename="package://dreamer/models/dreamer/meka_description/meshes/gripper_v0/l_finger.dae"/>
      </geometry>
      <material name="Grey"/>
    </visual>
    <collision>
      <origin rpy="0 0 0" xyz="0 0 0"/>
      <geometry>
        <mesh filename="package://dreamer/models/dreamer/meka_description/meshes/gripper_v0/l_finger.stl"/>
      </geometry>
    </collision>
  </link>
  <!-- Finger proximal digit -->
  <joint name="l_gripper_r_finger_joint" type="revolute">
    <axis xyz="0 0 -1"/>
    <origin rpy="0 0 0" xyz="0.07691 -0.01 0"/>
    <!-- limits on passive finger and finger top joints without
         transmission are not enforced by safety controllers.
         The lower/upper limits and are enforced in PR2 simulation and
         effort and velocity limits are ignored. This is also needed because
         these joints are declared revolute rather than continuous.-->
    <limit effort="1000.0" lower="0.0" upper="0.548" velocity="0.5"/>
    <dynamics damping="0.02"/>
    <mimic joint="l_gripper_l_finger_joint" multiplier="1" offset="0"/>
    <parent link="l_gripper_palm_link"/>
    <child link="l_gripper_r_finger_link"/>
  </joint>
  <link name="l_gripper_r_finger_link">
    <inertial>
      <mass value="0.17389"/>
      <origin rpy="0 0 0" xyz="0.03576 -0.01736 -0.00095"/>
      <inertia ixx="0.001" ixy="0.0" ixz="0.0" iyy="0.001" iyz="0.0" izz="0.001"/>
    </inertial>
    <visual>
      <origin rpy="3.14159265359 0 0" xyz="0 0 0"/>
      <geometry>
        <mesh filename="package://dreamer/models/dreamer/meka_description/meshes/gripper_v0/l_finger.dae"/>
      </geometry>
      <material name="Grey"/>
    </visual>
    <collision>
      <origin rpy="3.14159265359 0 0" xyz="0 0 0"/>
      <geometry>
        <mesh filename="package://dreamer/models/dreamer/meka_description/meshes/gripper_v0/l_finger.stl"/>
      </geometry>
    </collision>
  </link>
  <!-- Finger tip -->
  <joint name="l_gripper_l_finger_tip_joint" type="revolute">
    <axis xyz="0 0 -1"/>
    <origin rpy="0 0 0" xyz="0.09137 0.00495 0"/>
    <!-- limits on passive finger and finger top joints without
         transmission are not enforced by safety controllers.
         The lower/upper limits and are enforced in PR2 simulation and
         effort and velocity limits are ignored. This is also needed because
         these joints are declared revolute rather than continuous.-->
    <limit effort="1000.0" lower="0.0" upper="0.548" velocity="0.5"/>
    <dynamics damping="0.001"/>
    <mimic joint="l_gripper_l_finger_joint" multiplier="1" offset="0"/>
    <parent link="l_gripper_l_finger_link"/>
    <child link="l_gripper_l_finger_tip_link"/>
  </joint>
  <link name="l_gripper_l_finger_tip_link">
    <inertial>
      <mass value="0.04419"/>
      <origin rpy="0 0 0" xyz="0.00423 0.00284 0.0"/>
      <inertia ixx="0.001" ixy="0.0" ixz="0.0" iyy="0.001" iyz="0.0" izz="0.001"/>
    </inertial>
    <visual>
      <origin rpy="0 0 0" xyz="0 0 0"/>
      <geometry>
        <mesh filename="package://dreamer/models/dreamer/meka_description/meshes/gripper_v0/l_finger_tip.dae"/>
      </geometry>
      <material name="Green"/>
    </visual>
    <collision>
      <origin rpy="0 0 0" xyz="0 0 0"/>
      <geometry>
        <mesh filename="package://dreamer/models/dreamer/meka_description/meshes/gripper_v0/l_finger_tip.stl"/>
      </geometry>
    </collision>
  </link>
  <!-- Finger tip -->
  <joint name="l_gripper_r_finger_tip_joint" type="revolute">
    <axis xyz="0 0 1"/>
    <origin rpy="0 0 0" xyz="0.09137 -0.00495 0"/>
    <!-- limits on passive finger and finger top joints without
         transmission are not enforced by safety controllers.
         The lower/upper limits and are enforced in PR2 simulation and
         effort and velocity limits are ignored. This is also needed because
         these joints are declared revolute rather than continuous.-->
    <limit effort="1000.0" lower="0.0" upper="0.548" velocity="0.5"/>
    <dynamics damping="0.001"/>
    <mimic joint="l_gripper_l_finger_joint" multiplier="1" offset="0"/>
    <parent link="l_gripper_r_finger_link"/>
    <child link="l_gripper_r_finger_tip_link"/>
  </joint>
  <link name="l_gripper_r_finger_tip_link">
    <inertial>
      <mass value="0.04419"/>
      <origin rpy="0 0 0" xyz="0.00423 -0.00284 0.0"/>
      <inertia ixx="0.001" ixy="0.0" ixz="0.0" iyy="0.001" iyz="0.0" izz="0.001"/>
    </inertial>
    <visual>
      <origin rpy="3.14159265359 0 0" xyz="0 0 0"/>
      <geometry>
        <mesh filename="package://dreamer/models/dreamer/meka_description/meshes/gripper_v0/l_finger_tip.dae"/>
      </geometry>
      <material name="Green"/>
    </visual>
    <collision>
      <origin rpy="3.14159265359 0 0" xyz="0 0 0"/>
      <geometry>
        <mesh filename="package://dreamer/models/dreamer/meka_description/meshes/gripper_v0/l_finger_tip.stl"/>
      </geometry>
    </collision>
  </link>
  <link name="world">
    <!-- Virtual Link -->
    <inertial>
      <mass value="0.1"/>
      <origin rpy="0 0 0" xyz="0 0 1.2"/>
      <inertia ixx="8.33333333333e-05" ixy="0.0" ixz="0.0" iyy="8.33333333333e-05" iyz="0.0" izz="0.000125"/>
    </inertial>
  </link>
  <joint name="panplateOffset" type="fixed">
    <origin rpy="0 0 0" xyz="0 0 0"/>
    <axis xyz="0 0 1"/>
    <parent link="world"/>
    <child link="panplate_link"/>
  </joint>
</robot>

